<?xml version='1.0'?>
<robot name="slam_bot_four_wheel" 
  xmlns:xacro="http://www.ros.org/wiki/xacro">
  <xacro:include filename="$(find slam_project)/urdf/slam_bot.gazebo" />
  <link name="robot_footprint"></link>
  <joint name="robot_footprint_joint" type="fixed">
    <origin xyz="0 0 0" rpy="0 0 0" />
    <parent link="robot_footprint"/>
    <child link="chassis" />
  </joint>
  <link name='chassis'>
    <pose>0 0 0.1 0 0 0</pose>
    <inertial>
      <mass value="50.0"/>
      <origin xyz="0.0 0 0" rpy=" 0 0 0"/>
      <inertia ixx="0.1" ixy="0" ixz="0" iyy="0.1" iyz="0" izz="0.1" />
    </inertial>
    <collision name='collision'>
      <origin xyz="0 0 0" rpy=" 0 0 0"/>
      <geometry>
        <box size=".4 .2 .1"/>
      </geometry>
    </collision>
    <visual name='chassis_visual'>
      <origin xyz="0 0 0" rpy=" 0 0 0"/>
      <geometry>
        <box size=".4 .2 .1"/>
      </geometry>
    </visual>
    <collision name='back_caster_collision'>
      <origin xyz="-0.15 0 -0.05" rpy=" 0 0 0"/>
      <geometry>
        <sphere radius="0.049"/>
      </geometry>
      <surface>
        <friction>
          <ode>
            <mu>0.1</mu>
            <mu2>0.1</mu2>
            <slip1>0.</slip1>
            <slip2>0.</slip2>
          </ode>
        </friction>
      </surface>
    </collision>
    <visual name='back_caster_visual'>
      <origin xyz="-0.15 0 -0.05" rpy=" 0 0 0"/>
      <geometry>
        <sphere radius="0.05"/>
      </geometry>
    </visual>
    <collision name='front_caster_collision'>
      <origin xyz="0.15 0 -0.05" rpy=" 0 0 0"/>
      <geometry>
        <sphere radius="0.049"/>
      </geometry>
      <surface>
        <friction>
          <ode>
            <mu>0.1</mu>
            <mu2>0.1</mu2>
            <slip1>0.0</slip1>
            <slip2>0.0</slip2>

          </ode>
        </friction>
      </surface>
    </collision>
    <visual name='front_caster_visual'>
      <origin xyz="0.15 0.0 -0.05" rpy=" 0 0 0"/>
      <geometry>
        <sphere radius="0.05"/>
      </geometry>
    </visual>
  </link>
  <link name="front_left_wheel">
    <inertial>
      <origin xyz="0.0 0.0 0.0" rpy="0.0 1.5707 1.5707" />
      <mass value="5.0"/>
      <inertia ixx="0.1" ixy="0" ixz="0" iyy="0.1" iyz="0" izz="0.1" />
    </inertial>
    <collision name='collision'>
      <origin xyz="0.0 0.0 0.0" rpy=" 0 1.5707 1.5707"/>
      <geometry>
        <cylinder radius="0.1" length="0.05"/>
      </geometry>
    </collision>
    <visual name="lef_wheel_visual">
      <origin xyz="0.0 0.0 0.0" rpy="0 1.5707 1.5707" />
      <geometry>
        <cylinder radius="0.1" length="0.05"/>
      </geometry>
    </visual>
  </link>
  <joint type="continuous" name="front_left_wheel_hinge">
    <origin xyz="0.15 0.15 0.0" rpy="0 0 0"/>
    <child link="front_left_wheel"/>
    <parent link="chassis"/>
    <axis xyz="0 1 0" rpy="0 0 0"/>
    <limit effort="10000" velocity="1000"/>
    <!-- increased damping to reduce the osscilations when robot stops getting acceleration -->
    <joint_properties damping="10.0" friction="1.0"/>
  </joint>
  <link name="front_right_wheel">
    <inertial>
      <origin xyz="0.0 0.0 0.0" rpy="0.0 1.5707 1.5707" />
      <mass value="5.0"/>
      <inertia ixx="0.1" ixy="0" ixz="0" iyy="0.1" iyz="0" izz="0.1" />
    </inertial>
    <collision name='collision'>
      <origin xyz="0.0 0.0 0.0" rpy=" 0 1.5707 1.5707"/>
      <geometry>
        <cylinder radius="0.1" length="0.05"/>
      </geometry>
    </collision>
    <visual name="right_wheel_visual"> 
      <origin xyz="0.0 0.0 0.0" rpy="0 1.5707 1.5707" />
      <geometry>
        <cylinder radius="0.1" length="0.05"/>
      </geometry>
    </visual>
  </link>
  <joint type="continuous" name="front_right_wheel_hinge">
    <origin xyz="0.15 -0.15 0.0" rpy="0 0 0"/>
    <child link="front_right_wheel"/>
    <parent link="chassis"/>
    <axis xyz="0 1 0" rpy="0 0 0"/>
    <limit effort="10000" velocity="1000"/>
    <!-- increased damping to reduce the osscilations when robot stops getting acceleration -->
    <joint_properties damping="10.0" friction="1.0"/>
  </joint>

  <link name="back_left_wheel">
    <inertial>
      <origin xyz="0.0 0.0 0.0" rpy="0.0 1.5707 1.5707" />
      <mass value="5.0"/>
      <inertia ixx="0.1" ixy="0" ixz="0" iyy="0.1" iyz="0" izz="0.1" />
    </inertial>
    <collision name='collision'>
      <origin xyz="0.0 0.0 0.0" rpy=" 0 1.5707 1.5707"/>
      <geometry>
        <cylinder radius="0.1" length="0.05"/>
      </geometry>
    </collision>
    <visual name="lef_wheel_visual">
      <origin xyz="0.0 0.0 0.0" rpy="0 1.5707 1.5707" />
      <geometry>
        <cylinder radius="0.1" length="0.05"/>
      </geometry>
    </visual>
  </link>
  <joint type="continuous" name="back_left_wheel_hinge">
    <origin xyz="-0.15 0.15 0.0" rpy="0 0 0"/>
    <child link="back_left_wheel"/>
    <parent link="chassis"/>
    <axis xyz="0 1 0" rpy="0 0 0"/>
    <limit effort="10000" velocity="1000"/>
    <!-- increased damping to reduce the osscilations when robot stops getting acceleration -->
    <joint_properties damping="10.0" friction="1.0"/>
  </joint>
  <link name="back_right_wheel">
    <inertial>
      <origin xyz="0.0 0.0 0.0" rpy="0.0 1.5707 1.5707" />
      <mass value="5.0"/>
      <inertia ixx="0.1" ixy="0" ixz="0" iyy="0.1" iyz="0" izz="0.1" />
    </inertial>
    <collision name='collision'>
      <origin xyz="0.0 0.0 0.0" rpy=" 0 1.5707 1.5707"/>
      <geometry>
        <cylinder radius="0.1" length="0.05"/>
      </geometry>
    </collision>
    <visual name="right_wheel_visual"> 
      <origin xyz="0.0 0.0 0.0" rpy="0 1.5707 1.5707" />
      <geometry>
        <cylinder radius="0.1" length="0.05"/>
      </geometry>
    </visual>
  </link>
  <joint type="continuous" name="back_right_wheel_hinge">
    <origin xyz="-0.15 -0.15 0.0" rpy="0 0 0"/>
    <child link="back_right_wheel"/>
    <parent link="chassis"/>
    <axis xyz="0 1 0" rpy="0 0 0"/>
    <limit effort="10000" velocity="1000"/>
    <!-- increased damping to reduce the osscilations when robot stops getting acceleration -->
    <joint_properties damping="10.0" friction="1.0"/>
  </joint>

<!--Camera-->
  <link name="camera">
    <origin>0 0 0 0 0 0</origin>
    <inertial>
      <origin xyz="0 0 0" rpy="3.14 0 0"/>
      <mass value ="0.1"/>
      <inertia ixx="1e-6" ixy="0" ixz="0" iyy="1e-6" iyz="0" izz="1e-6"/>
    </inertial>
    <collision name="collision">
      <origin xyz="0 0 0" rpy="3.14 0 0"/>
      <geometry>
        <box size="0.05 0.05 0.05" />
      </geometry>
    </collision>
    <visual>
      <geometry>
        <mesh filename="package://slam_project/meshes/kinect/meshes/kinect.dae" />
      </geometry>
    </visual>
  </link>

  <joint type="fixed" name="camera_joint">
    <origin xyz="0.3 0 0" rpy="0 0 0" />
    <child link="camera" />
    <parent link="chassis" />
  </joint>

  <joint name="camera_optical_joint" type="fixed">
    <!-- these values have to be these values otherwise the gazebo camera
        image won't be aligned properly with the frame it is supposedly
        originating from -->
    <origin xyz="0 0 0" rpy="${-pi/2} 0 ${-pi/2}"/>
    <parent link="camera"/>
    <child link="camera_optical_link"/>
  </joint>

  <link name="camera_optical_link">
    </link>
  
<!--LIDAR-->
  <link name="hokuyo">
      <origin>0. 0 0 0 0 0</origin>
      <inertial>
        <origin xyz="0 0 0" rpy="0 0 0"/>
        <mass value ="0.1"/>
        <inertia ixx="1e-6" ixy="0" ixz="0" iyy="1e-6" iyz="0" izz="1e-6"/>
      </inertial>
      <collision name="collision">
        <origin xyz="0 0 0" rpy="0 0 0"/>
        <geometry>
          <box size="0.1 0.1 0.1" />
        </geometry>
      </collision>
      <visual>
        <geometry>
          <mesh filename="package://slam_project/meshes/hokuyo.dae" />
        </geometry>
      </visual>
  </link>
  <joint type="fixed" name="hokuyo_joint">
    <origin xyz="0.2 0 0.15" rpy="0 0 0"/>
    <child link="hokuyo" />
    <parent link="chassis" />
  </joint>

</robot>